Workbook

Sheet Call Log
A1: Date | B1: Contact Name | C1: Company | D1: Source | E1: Outcome | F1: Notes
A2: 2026-07-06 | B2: Jane Doe | C2: Acme Inc. | D2: Warm Market | E2: Appointment Set | F2: Interested in RRSP review
A3: 46215 | B3: Jane Doe | D3: Friend | E3: No Answer | F3: Call Back

Sheet Appointment Log
A1: Date | B1: Contact Name | C1: Type | D1: Status | E1: Expected Premium ($) | F1: Referrals Given | G1: Notes
A2: 2026-07-08 | B2: Jane Doe | C2: Initial Meeting | D2: Held | E2: 85 | F2: 1 | G2: Discussed TFSA vs RRSP options

Sheet Sales Log
A1: Date | B1: Client Name | C1: Product Type | D1: Premium Amount | E1: Notes
A2: 2026-07-09 | B2: Jane Doe | C2: Universal Life | D2: 85 | E2: First-year premium, monthly mode

Sheet Recruiting Log
A1: Date | B1: Prospect Name | C1: Source | D1: Status | E1: Notes
A2: 2026-07-07 | B2: Alex Kumar | C2: Referral | D2: Interview Scheduled | E2: Ex-colleague, interested in side income

Sheet Daily Log
A1: Date | B1: Calls Made | C1: Appts Set | D1: Appts Held | E1: Premium ($) | F1: Recruiting Conv. | G1: Min Met | H1: Streak | I1: Daily Notes
A2: 2026-07-06 | B2: =COUNTIF('Call Log'!$A$3:$A$301,A2) -> 0 | C2: =COUNTIFS('Call Log'!$A$3:$A$301,A2,'Call Log'!$E$3:$E$301,"Appointment Set")+COUNTIFS('Appointment Log'!$A$3:$A$301,A2,'Appointment Log'!$C$3:$C$301,"Initial Meeting") -> 0 | D2: =COUNTIFS('Appointment Log'!$A$3:$A$301,A2,'Appointment Log'!$D$3:$D$301,"Held") -> 0 | E2: =SUMIF('Sales Log'!$A$3:$A$201,A2,'Sales Log'!$D$3:$D$201) -> 0 | F2: =COUNTIF('Recruiting Log'!$A$3:$A$151,A2) -> 0 | G2: =IF(B2>=Dashboard!$B$5,1,0) -> 0 | H2: =IF(A2>TODAY(),"",IF(G2=1,1,0))
A3: =A2+1 -> 46210 | B3: =COUNTIF('Call Log'!$A$3:$A$301,A3) -> 0 | C3: =COUNTIFS('Call Log'!$A$3:$A$301,A3,'Call Log'!$E$3:$E$301,"Appointment Set")+COUNTIFS('Appointment Log'!$A$3:$A$301,A3,'Appointment Log'!$C$3:$C$301,"Initial Meeting") -> 0 | D3: =COUNTIFS('Appointment Log'!$A$3:$A$301,A3,'Appointment Log'!$D$3:$D$301,"Held") -> 0 | E3: =SUMIF('Sales Log'!$A$3:$A$201,A3,'Sales Log'!$D$3:$D$201) -> 0 | F3: =COUNTIF('Recruiting Log'!$A$3:$A$151,A3) -> 0 | G3: =IF(B3>=Dashboard!$B$5,1,0) -> 0 | H3: =IF(A3>TODAY(),"",IF(G3=1,IF(ISNUMBER(H2),H2+1,1),0)) -> 0
A4: =A3+1 -> 46211 | B4: =COUNTIF('Call Log'!$A$3:$A$301,A4) -> 0 | C4: =COUNTIFS('Call Log'!$A$3:$A$301,A4,'Call Log'!$E$3:$E$301,"Appointment Set")+COUNTIFS('Appointment Log'!$A$3:$A$301,A4,'Appointment Log'!$C$3:$C$301,"Initial Meeting") -> 0 | D4: =COUNTIFS('Appointment Log'!$A$3:$A$301,A4,'Appointment Log'!$D$3:$D$301,"Held") -> 0 | E4: =SUMIF('Sales Log'!$A$3:$A$201,A4,'Sales Log'!$D$3:$D$201) -> 0 | F4: =COUNTIF('Recruiting Log'!$A$3:$A$151,A4) -> 0 | G4: =IF(B4>=Dashboard!$B$5,1,0) -> 0 | H4: =IF(A4>TODAY(),"",IF(G4=1,IF(ISNUMBER(H3),H3+1,1),0)) -> 0
A5: =A4+1 -> 46212 | B5: =COUNTIF('Call Log'!$A$3:$A$301,A5) -> 0 | C5: =COUNTIFS('Call Log'!$A$3:$A$301,A5,'Call Log'!$E$3:$E$301,"Appointment Set")+COUNTIFS('Appointment Log'!$A$3:$A$301,A5,'Appointment Log'!$C$3:$C$301,"Initial Meeting") -> 0 | D5: =COUNTIFS('Appointment Log'!$A$3:$A$301,A5,'Appointment Log'!$D$3:$D$301,"Held") -> 0 | E5: =SUMIF('Sales Log'!$A$3:$A$201,A5,'Sales Log'!$D$3:$D$201) -> 0 | F5: =COUNTIF('Recruiting Log'!$A$3:$A$151,A5) -> 0 | G5: =IF(B5>=Dashboard!$B$5,1,0) -> 0 | H5: =IF(A5>TODAY(),"",IF(G5=1,IF(ISNUMBER(H4),H4+1,1),0)) -> 0
A6: =A5+1 -> 46213 | B6: =COUNTIF('Call Log'!$A$3:$A$301,A6) -> 0 | C6: =COUNTIFS('Call Log'!$A$3:$A$301,A6,'Call Log'!$E$3:$E$301,"Appointment Set")+COUNTIFS('Appointment Log'!$A$3:$A$301,A6,'Appointment Log'!$C$3:$C$301,"Initial Meeting") -> 0 | D6: =COUNTIFS('Appointment Log'!$A$3:$A$301,A6,'Appointment Log'!$D$3:$D$301,"Held") -> 0 | E6: =SUMIF('Sales Log'!$A$3:$A$201,A6,'Sales Log'!$D$3:$D$201) -> 0 | F6: =COUNTIF('Recruiting Log'!$A$3:$A$151,A6) -> 0 | G6: =IF(B6>=Dashboard!$B$5,1,0) -> 0 | H6: =IF(A6>TODAY(),"",IF(G6=1,IF(ISNUMBER(H5),H5+1,1),0)) -> 0
A7: =A6+1 -> 46214 | B7: =COUNTIF('Call Log'!$A$3:$A$301,A7) -> 0 | C7: =COUNTIFS('Call Log'!$A$3:$A$301,A7,'Call Log'!$E$3:$E$301,"Appointment Set")+COUNTIFS('Appointment Log'!$A$3:$A$301,A7,'Appointment Log'!$C$3:$C$301,"Initial Meeting") -> 0 | D7: =COUNTIFS('Appointment Log'!$A$3:$A$301,A7,'Appointment Log'!$D$3:$D$301,"Held") -> 0 | E7: =SUMIF('Sales Log'!$A$3:$A$201,A7,'Sales Log'!$D$3:$D$201) -> 0 | F7: =COUNTIF('Recruiting Log'!$A$3:$A$151,A7) -> 0 | G7: =IF(B7>=Dashboard!$B$5,1,0) -> 0 | H7: =IF(A7>TODAY(),"",IF(G7=1,IF(ISNUMBER(H6),H6+1,1),0)) -> 0
A8: =A7+1 -> 46215 | B8: =COUNTIF('Call Log'!$A$3:$A$301,A8) -> 1 | C8: =COUNTIFS('Call Log'!$A$3:$A$301,A8,'Call Log'!$E$3:$E$301,"Appointment Set")+COUNTIFS('Appointment Log'!$A$3:$A$301,A8,'Appointment Log'!$C$3:$C$301,"Initial Meeting") -> 0 | D8: =COUNTIFS('Appointment Log'!$A$3:$A$301,A8,'Appointment Log'!$D$3:$D$301,"Held") -> 0 | E8: =SUMIF('Sales Log'!$A$3:$A$201,A8,'Sales Log'!$D$3:$D$201) -> 0 | F8: =COUNTIF('Recruiting Log'!$A$3:$A$151,A8) -> 0 | G8: =IF(B8>=Dashboard!$B$5,1,0) -> 0 | H8: =IF(A8>TODAY(),"",IF(G8=1,IF(ISNUMBER(H7),H7+1,1),0)) -> 0
A9: =A8+1 -> 46216 | B9: =COUNTIF('Call Log'!$A$3:$A$301,A9) -> 0 | C9: =COUNTIFS('Call Log'!$A$3:$A$301,A9,'Call Log'!$E$3:$E$301,"Appointment Set")+COUNTIFS('Appointment Log'!$A$3:$A$301,A9,'Appointment Log'!$C$3:$C$301,"Initial Meeting") -> 0 | D9: =COUNTIFS('Appointment Log'!$A$3:$A$301,A9,'Appointment Log'!$D$3:$D$301,"Held") -> 0 | E9: =SUMIF('Sales Log'!$A$3:$A$201,A9,'Sales Log'!$D$3:$D$201) -> 0 | F9: =COUNTIF('Recruiting Log'!$A$3:$A$151,A9) -> 0 | G9: =IF(B9>=Dashboard!$B$5,1,0) -> 0 | H9: =IF(A9>TODAY(),"",IF(G9=1,IF(ISNUMBER(H8),H8+1,1),0)) -> 0
A10: =A9+1 -> 46217 | B10: =COUNTIF('Call Log'!$A$3:$A$301,A10) -> 0 | C10: =COUNTIFS('Call Log'!$A$3:$A$301,A10,'Call Log'!$E$3:$E$301,"Appointment Set")+COUNTIFS('Appointment Log'!$A$3:$A$301,A10,'Appointment Log'!$C$3:$C$301,"Initial Meeting") -> 0 | D10: =COUNTIFS('Appointment Log'!$A$3:$A$301,A10,'Appointment Log'!$D$3:$D$301,"Held") -> 0 | E10: =SUMIF('Sales Log'!$A$3:$A$201,A10,'Sales Log'!$D$3:$D$201) -> 0 | F10: =COUNTIF('Recruiting Log'!$A$3:$A$151,A10) -> 0 | G10: =IF(B10>=Dashboard!$B$5,1,0) -> 0 | H10: =IF(A10>TODAY(),"",IF(G10=1,IF(ISNUMBER(H9),H9+1,1),0)) -> 0
A11: =A10+1 -> 46218 | B11: =COUNTIF('Call Log'!$A$3:$A$301,A11) -> 0 | C11: =COUNTIFS('Call Log'!$A$3:$A$301,A11,'Call Log'!$E$3:$E$301,"Appointment Set")+COUNTIFS('Appointment Log'!$A$3:$A$301,A11,'Appointment Log'!$C$3:$C$301,"Initial Meeting") -> 0 | D11: =COUNTIFS('Appointment Log'!$A$3:$A$301,A11,'Appointment Log'!$D$3:$D$301,"Held") -> 0 | E11: =SUMIF('Sales Log'!$A$3:$A$201,A11,'Sales Log'!$D$3:$D$201) -> 0 | F11: =COUNTIF('Recruiting Log'!$A$3:$A$151,A11) -> 0 | G11: =IF(B11>=Dashboard!$B$5,1,0) -> 0 | H11: =IF(A11>TODAY(),"",IF(G11=1,IF(ISNUMBER(H10),H10+1,1),0))
A12: =A11+1 -> 46219 | B12: =COUNTIF('Call Log'!$A$3:$A$301,A12) -> 0 | C12: =COUNTIFS('Call Log'!$A$3:$A$301,A12,'Call Log'!$E$3:$E$301,"Appointment Set")+COUNTIFS('Appointment Log'!$A$3:$A$301,A12,'Appointment Log'!$C$3:$C$301,"Initial Meeting") -> 0 | D12: =COUNTIFS('Appointment Log'!$A$3:$A$301,A12,'Appointment Log'!$D$3:$D$301,"Held") -> 0 | E12: =SUMIF('Sales Log'!$A$3:$A$201,A12,'Sales Log'!$D$3:$D$201) -> 0 | F12: =COUNTIF('Recruiting Log'!$A$3:$A$151,A12) -> 0 | G12: =IF(B12>=Dashboard!$B$5,1,0) -> 0 | H12: =IF(A12>TODAY(),"",IF(G12=1,IF(ISNUMBER(H11),H11+1,1),0))
A13: =A12+1 -> 46220 | B13: =COUNTIF('Call Log'!$A$3:$A$301,A13) -> 0 | C13: =COUNTIFS('Call Log'!$A$3:$A$301,A13,'Call Log'!$E$3:$E$301,"Appointment Set")+COUNTIFS('Appointment Log'!$A$3:$A$301,A13,'Appointment Log'!$C$3:$C$301,"Initial Meeting") -> 0 | D13: =COUNTIFS('Appointment Log'!$A$3:$A$301,A13,'Appointment Log'!$D$3:$D$301,"Held") -> 0 | E13: =SUMIF('Sales Log'!$A$3:$A$201,A13,'Sales Log'!$D$3:$D$201) -> 0 | F13: =COUNTIF('Recruiting Log'!$A$3:$A$151,A13) -> 0 | G13: =IF(B13>=Dashboard!$B$5,1,0) -> 0 | H13: =IF(A13>TODAY(),"",IF(G13=1,IF(ISNUMBER(H12),H12+1,1),0))
A14: =A13+1 -> 46221 | B14: =COUNTIF('Call Log'!$A$3:$A$301,A14) -> 0 | C14: =COUNTIFS('Call Log'!$A$3:$A$301,A14,'Call Log'!$E$3:$E$301,"Appointment Set")+COUNTIFS('Appointment Log'!$A$3:$A$301,A14,'Appointment Log'!$C$3:$C$301,"Initial Meeting") -> 0 | D14: =COUNTIFS('Appointment Log'!$A$3:$A$301,A14,'Appointment Log'!$D$3:$D$301,"Held") -> 0 | E14: =SUMIF('Sales Log'!$A$3:$A$201,A14,'Sales Log'!$D$3:$D$201) -> 0 | F14: =COUNTIF('Recruiting Log'!$A$3:$A$151,A14) -> 0 | G14: =IF(B14>=Dashboard!$B$5,1,0) -> 0 | H14: =IF(A14>TODAY(),"",IF(G14=1,IF(ISNUMBER(H13),H13+1,1),0))
... A62: =A61+1 -> 46269 | B62: =COUNTIF('Call Log'!$A$3:$A$301,A62) -> 0 | C62: =COUNTIFS('Call Log'!$A$3:$A$301,A62,'Call Log'!$E$3:$E$301,"Appointment Set")+COUNTIFS('Appointment Log'!$A$3:$A$301,A62,'Appointment Log'!$C$3:$C$301,"Initial Meeting") -> 0 | D62: =COUNTIFS('Appointment Log'!$A$3:$A$301,A62,'Appointment Log'!$D$3:$D$301,"Held") -> 0 | E62: =SUMIF('Sales Log'!$A$3:$A$201,A62,'Sales Log'!$D$3:$D$201) -> 0 | F62: =COUNTIF('Recruiting Log'!$A$3:$A$151,A62) -> 0 | G62: =IF(B62>=Dashboard!$B$5,1,0) -> 0 | H62: =IF(A62>TODAY(),"",IF(G62=1,IF(ISNUMBER(H61),H61+1,1),0))
A64: Note: Row 2's date is your start date. Rows auto-increment daily and auto-pull from all logs. 'Min Met' checks against the daily call minimum set on the Dashboard. 'Streak' is your consecutive-day count of hitting that minimum, through today.

Sheet Dashboard
A1: WFG Weekly Report
A3: Week Of (Monday): | B3: 2026-07-06 | D3: Calls Target/Wk: | E3: 50
A4: Appts Held Target/Wk: | B4: 3 | D4: Premium Target/Wk ($): | E4: 188
A5: Min Calls/Day (Streak): | B5: 15 | D5: MD Deadline: | E5: 46249
A6: Edit the gold cells above - everything below updates automatically.
A8: This Week: Target vs Actual
A9: Metric | B9: Target | C9: Actual | D9: % to Goal
A10: Calls Made | B10: =E3 -> 50 | C10: =COUNTIFS('Call Log'!$A$3:$A$301,">="&$B$3,'Call Log'!$A$3:$A$301,"<"&$B$3+7) -> 1 | D10: =IFERROR(C10/B10,0) -> 0.02
A11: Appointments Held | B11: =B4 -> 3 | C11: =COUNTIFS('Appointment Log'!$A$3:$A$301,">="&$B$3,'Appointment Log'!$A$3:$A$301,"<"&$B$3+7,'Appointment Log'!$D$3:$D$301,"Held") -> 0 | D11: =IFERROR(C11/B11,0) -> 0
A12: Premium ($) | B12: =E4 -> 188 | C12: =SUMIFS('Sales Log'!$D$3:$D$201,'Sales Log'!$A$3:$A$201,">="&$B$3,'Sales Log'!$A$3:$A$201,"<"&$B$3+7) -> 0 | D12: =IFERROR(C12/B12,0) -> 0
A14: Call Outcomes (Selected Week) | D14: Appointment Status (Selected Week) | G14: Call Source (Selected Week)
A16: Status | B16: Count | D16: Status | E16: Count | G16: Source | H16: Count
A17: Connected | B17: =COUNTIFS('Call Log'!$A$3:$A$301,">="&$B$3,'Call Log'!$A$3:$A$301,"<"&$B$3+7,'Call Log'!$E$3:$E$301,A17) -> 0 | D17: Scheduled | E17: =COUNTIFS('Appointment Log'!$A$3:$A$301,">="&$B$3,'Appointment Log'!$A$3:$A$301,"<"&$B$3+7,'Appointment Log'!$D$3:$D$301,D17) -> 0 | G17: Warm Market | H17: =COUNTIFS('Call Log'!$A$3:$A$301,">="&$B$3,'Call Log'!$A$3:$A$301,"<"&$B$3+7,'Call Log'!$D$3:$D$301,G17) -> 0
A18: Voicemail | B18: =COUNTIFS('Call Log'!$A$3:$A$301,">="&$B$3,'Call Log'!$A$3:$A$301,"<"&$B$3+7,'Call Log'!$E$3:$E$301,A18) -> 0 | D18: Held | E18: =COUNTIFS('Appointment Log'!$A$3:$A$301,">="&$B$3,'Appointment Log'!$A$3:$A$301,"<"&$B$3+7,'Appointment Log'!$D$3:$D$301,D18) -> 0 | G18: Referral | H18: =COUNTIFS('Call Log'!$A$3:$A$301,">="&$B$3,'Call Log'!$A$3:$A$301,"<"&$B$3+7,'Call Log'!$D$3:$D$301,G18) -> 0
A19: No Answer | B19: =COUNTIFS('Call Log'!$A$3:$A$301,">="&$B$3,'Call Log'!$A$3:$A$301,"<"&$B$3+7,'Call Log'!$E$3:$E$301,A19) -> 1 | D19: No-Show | E19: =COUNTIFS('Appointment Log'!$A$3:$A$301,">="&$B$3,'Appointment Log'!$A$3:$A$301,"<"&$B$3+7,'Appointment Log'!$D$3:$D$301,D19) -> 0 | G19: Cold | H19: =COUNTIFS('Call Log'!$A$3:$A$301,">="&$B$3,'Call Log'!$A$3:$A$301,"<"&$B$3+7,'Call Log'!$D$3:$D$301,G19) -> 0
A20: Appointment Set | B20: =COUNTIFS('Call Log'!$A$3:$A$301,">="&$B$3,'Call Log'!$A$3:$A$301,"<"&$B$3+7,'Call Log'!$E$3:$E$301,A20) -> 0 | D20: Rescheduled | E20: =COUNTIFS('Appointment Log'!$A$3:$A$301,">="&$B$3,'Appointment Log'!$A$3:$A$301,"<"&$B$3+7,'Appointment Log'!$D$3:$D$301,D20) -> 0 | G20: Social Media | H20: =COUNTIFS('Call Log'!$A$3:$A$301,">="&$B$3,'Call Log'!$A$3:$A$301,"<"&$B$3+7,'Call Log'!$D$3:$D$301,G20) -> 0
A21: Not Interested | B21: =COUNTIFS('Call Log'!$A$3:$A$301,">="&$B$3,'Call Log'!$A$3:$A$301,"<"&$B$3+7,'Call Log'!$E$3:$E$301,A21) -> 0 | D21: Cancelled | E21: =COUNTIFS('Appointment Log'!$A$3:$A$301,">="&$B$3,'Appointment Log'!$A$3:$A$301,"<"&$B$3+7,'Appointment Log'!$D$3:$D$301,D21) -> 0 | G21: Friend | H21: =COUNTIFS('Call Log'!$A$3:$A$301,">="&$B$3,'Call Log'!$A$3:$A$301,"<"&$B$3+7,'Call Log'!$D$3:$D$301,G21) -> 1
G22: Other | H22: =COUNTIFS('Call Log'!$A$3:$A$301,">="&$B$3,'Call Log'!$A$3:$A$301,"<"&$B$3+7,'Call Log'!$D$3:$D$301,G22) -> 0
A39: 8-Week Trend (ending Selected Week)
A40: Week Of | B40: Calls Made | C40: Calls Target | D40: Appts Held | E40: Premium ($) | F40: Premium Target
A41: =$B$3-49 -> 46160 | B41: =COUNTIFS('Call Log'!$A$3:$A$301,">="&A41,'Call Log'!$A$3:$A$301,"<"&A41+7) -> 0 | C41: =$E$3 -> 50 | D41: =COUNTIFS('Appointment Log'!$A$3:$A$301,">="&A41,'Appointment Log'!$A$3:$A$301,"<"&A41+7,'Appointment Log'!$D$3:$D$301,"Held") -> 0 | E41: =SUMIFS('Sales Log'!$D$3:$D$201,'Sales Log'!$A$3:$A$201,">="&A41,'Sales Log'!$A$3:$A$201,"<"&A41+7) -> 0 | F41: =$E$4 -> 188
A42: =$B$3-42 -> 46167 | B42: =COUNTIFS('Call Log'!$A$3:$A$301,">="&A42,'Call Log'!$A$3:$A$301,"<"&A42+7) -> 0 | C42: =$E$3 -> 50 | D42: =COUNTIFS('Appointment Log'!$A$3:$A$301,">="&A42,'Appointment Log'!$A$3:$A$301,"<"&A42+7,'Appointment Log'!$D$3:$D$301,"Held") -> 0 | E42: =SUMIFS('Sales Log'!$D$3:$D$201,'Sales Log'!$A$3:$A$201,">="&A42,'Sales Log'!$A$3:$A$201,"<"&A42+7) -> 0 | F42: =$E$4 -> 188
A43: =$B$3-35 -> 46174 | B43: =COUNTIFS('Call Log'!$A$3:$A$301,">="&A43,'Call Log'!$A$3:$A$301,"<"&A43+7) -> 0 | C43: =$E$3 -> 50 | D43: =COUNTIFS('Appointment Log'!$A$3:$A$301,">="&A43,'Appointment Log'!$A$3:$A$301,"<"&A43+7,'Appointment Log'!$D$3:$D$301,"Held") -> 0 | E43: =SUMIFS('Sales Log'!$D$3:$D$201,'Sales Log'!$A$3:$A$201,">="&A43,'Sales Log'!$A$3:$A$201,"<"&A43+7) -> 0 | F43: =$E$4 -> 188
A44: =$B$3-28 -> 46181 | B44: =COUNTIFS('Call Log'!$A$3:$A$301,">="&A44,'Call Log'!$A$3:$A$301,"<"&A44+7) -> 0 | C44: =$E$3 -> 50 | D44: =COUNTIFS('Appointment Log'!$A$3:$A$301,">="&A44,'Appointment Log'!$A$3:$A$301,"<"&A44+7,'Appointment Log'!$D$3:$D$301,"Held") -> 0 | E44: =SUMIFS('Sales Log'!$D$3:$D$201,'Sales Log'!$A$3:$A$201,">="&A44,'Sales Log'!$A$3:$A$201,"<"&A44+7) -> 0 | F44: =$E$4 -> 188
A45: =$B$3-21 -> 46188 | B45: =COUNTIFS('Call Log'!$A$3:$A$301,">="&A45,'Call Log'!$A$3:$A$301,"<"&A45+7) -> 0 | C45: =$E$3 -> 50 | D45: =COUNTIFS('Appointment Log'!$A$3:$A$301,">="&A45,'Appointment Log'!$A$3:$A$301,"<"&A45+7,'Appointment Log'!$D$3:$D$301,"Held") -> 0 | E45: =SUMIFS('Sales Log'!$D$3:$D$201,'Sales Log'!$A$3:$A$201,">="&A45,'Sales Log'!$A$3:$A$201,"<"&A45+7) -> 0 | F45: =$E$4 -> 188
A46: =$B$3-14 -> 46195 | B46: =COUNTIFS('Call Log'!$A$3:$A$301,">="&A46,'Call Log'!$A$3:$A$301,"<"&A46+7) -> 0 | C46: =$E$3 -> 50 | D46: =COUNTIFS('Appointment Log'!$A$3:$A$301,">="&A46,'Appointment Log'!$A$3:$A$301,"<"&A46+7,'Appointment Log'!$D$3:$D$301,"Held") -> 0 | E46: =SUMIFS('Sales Log'!$D$3:$D$201,'Sales Log'!$A$3:$A$201,">="&A46,'Sales Log'!$A$3:$A$201,"<"&A46+7) -> 0 | F46: =$E$4 -> 188
A47: =$B$3-7 -> 46202 | B47: =COUNTIFS('Call Log'!$A$3:$A$301,">="&A47,'Call Log'!$A$3:$A$301,"<"&A47+7) -> 0 | C47: =$E$3 -> 50 | D47: =COUNTIFS('Appointment Log'!$A$3:$A$301,">="&A47,'Appointment Log'!$A$3:$A$301,"<"&A47+7,'Appointment Log'!$D$3:$D$301,"Held") -> 0 | E47: =SUMIFS('Sales Log'!$D$3:$D$201,'Sales Log'!$A$3:$A$201,">="&A47,'Sales Log'!$A$3:$A$201,"<"&A47+7) -> 0 | F47: =$E$4 -> 188
A48: =$B$3-0 -> 46209 | B48: =COUNTIFS('Call Log'!$A$3:$A$301,">="&A48,'Call Log'!$A$3:$A$301,"<"&A48+7) -> 1 | C48: =$E$3 -> 50 | D48: =COUNTIFS('Appointment Log'!$A$3:$A$301,">="&A48,'Appointment Log'!$A$3:$A$301,"<"&A48+7,'Appointment Log'!$D$3:$D$301,"Held") -> 0 | E48: =SUMIFS('Sales Log'!$D$3:$D$201,'Sales Log'!$A$3:$A$201,">="&A48,'Sales Log'!$A$3:$A$201,"<"&A48+7) -> 0 | F48: =$E$4 -> 188
A68: Key Weekly Metrics
A69: Metric | B69: Value
A70: Dial-to-Connect Ratio (Wk) | B70: =IFERROR(B17/C10,0) -> 0
A71: No-Show Rate (Wk) | B71: =IFERROR(E19/SUM(E17:E21),0) -> 0
A72: Referrals Given (Wk) | B72: =SUMIFS('Appointment Log'!$F$3:$F$301,'Appointment Log'!$A$3:$A$301,">="&$B$3,'Appointment Log'!$A$3:$A$301,"<"&$B$3+7) -> 0
A73: Recruiting Conversations (Wk) | B73: =COUNTIFS('Recruiting Log'!$A$3:$A$151,">="&$B$3,'Recruiting Log'!$A$3:$A$151,"<"&$B$3+7) -> 0
A74: New Associates Licensed (All-Time) | B74: =COUNTIF('Recruiting Log'!$D$3:$D$151,"Licensed") -> 0
A75: Pipeline Value - Open Appts ($) | B75: =SUMIFS('Appointment Log'!$E$3:$E$301,'Appointment Log'!$D$3:$D$301,"Scheduled") -> 0
A76: Current Calling Streak (days) | B76: =IFERROR(LOOKUP(2,1/(ISNUMBER('Daily Log'!$H$2:$H$62)),'Daily Log'!$H$2:$H$62),0) -> 0
A77: 4-Week Rolling Avg Calls/Wk | B77: =AVERAGE(B45:B48) -> 0.25
A78: Days Remaining to MD Deadline | B78: =E5-TODAY() -> 32
A80: Conversion Funnel (Selected Week)
...
